Workbook

Sheet Leaderboard
A1: FIFA World Cup 2026 — Sweepstake Leaderboard
A2: Scores update automatically as results are entered in the Group Stage and Knockout & Winner tabs. Points: Group win 2 · Draw 1 · R32 qualify 3 · R16 5 · QF 8 · SF 12 · 3rd place 15 · Finalist 18 · Champion 25.
A4: Scoring System
A5: Group Win | B5: Group Draw | C5: Group Loss | D5: Reach R32 | E5: Reach R16 | F5: Reach QF | G5: Reach SF | H5: 3rd Place | I5: Finalist | J5: Champion
A6: 2 | B6: 1 | C6: 0 | E6: 5 | F6: 8 | G6: 12 | H6: 15 | I6: 18 | J6: 25
A8: LEADERBOARD
A9: Rank | B9: Member | C9: Group Pts | D9: Knockout Pts | E9: Total | F9: Teams Still In | G9: Best Remaining | L9: Team | M9: Member | N9: GrpPts | O9: KOPts | P9: Total | Q9: StillIn
A10: =RANK(E10,E$10:E$17,0) -> 1 | B10: Poppa | C10: =SUMIF(M$10:M$57,B10,N$10:N$57) -> 0 | D10: =SUMIF(M$10:M$57,B10,O$10:O$57) -> 0 | E10: =SUMIF(M$10:M$57,B10,P$10:P$57) -> 0 | F10: =COUNTIFS(M$10:M$57,B10,Q$10:Q$57,"Yes") -> 0 | G10: =IFERROR(INDEX(L$10:L$57,MATCH(_xludf.MAXIFS(P$10:P$57,M$10:M$57,B10,Q$10:Q$57,"Yes"),P$10:P$57,0)),"—") -> — | L10: Mexico | M10: =IFERROR(VLOOKUP(L10,'Participating Teams'!$B$4:$F$51,5,FALSE),"") -> 0 | N10: =IFERROR(INDEX('Group Stage'!$I$1:$I$200,MATCH(L10,'Group Stage'!$A$1:$A$200,0)),0) -> 0 | O10: =IF(AND('Knockout & Winner'!$G$59<>"",'Knockout & Winner'!$G$59=L10),25,IF(AND('Knockout & Winner'!$G$55<>"",'Knockout & Winner'!$G$55=L10),15,IF(OR(AND('Knockout & Winner'!$B$59<>"",'Knockout & Winner'!$B$59=L10),AND('Knockout & Winner'!$E$59<>"",'Knockout & Winner'!$E$59=L10)),18,IF(COUNTIF('Knockout & Winner'!$G$50:$G$51,L10)>0,12,IF(COUNTIF('Knockout & Winner'!$G$43:$G$46,L10)>0,8,IF(COUNTIF('Knockout & Winner'!$G$32:$G$39,L10)>0,5,IF(COUNTIF('Knockout & Winner'!$G$13:$G$28,L10)>0,3,0))))))) -> 0 | P10: =N10+O10 -> 0 | Q10: =IF(OR(COUNTIF('Knockout & Winner'!$G$13:$G$28,L10)>0,COUNTIF('Knockout & Winner'!$G$32:$G$39,L10)>0,COUNTIF('Knockout & Winner'!$G$43:$G$46,L10)>0,COUNTIF('Knockout & Winner'!$G$50:$G$51,L10)>0,'Knockout & Winner'!$G$55=L10,'Knockout & Winner'!$G$59=L10),"Yes","")
A11: =RANK(E11,E$10:E$17,0) -> 1 | B11: Nana | C11: =SUMIF(M$10:M$57,B11,N$10:N$57) -> 0 | D11: =SUMIF(M$10:M$57,B11,O$10:O$57) -> 0 | E11: =SUMIF(M$10:M$57,B11,P$10:P$57) -> 0 | F11: =COUNTIFS(M$10:M$57,B11,Q$10:Q$57,"Yes") -> 0 | G11: =IFERROR(INDEX(L$10:L$57,MATCH(_xludf.MAXIFS(P$10:P$57,M$10:M$57,B11,Q$10:Q$57,"Yes"),P$10:P$57,0)),"—") -> — | L11: South Korea | M11: =IFERROR(VLOOKUP(L11,'Participating Teams'!$B$4:$F$51,5,FALSE),"") -> 0 | N11: =IFERROR(INDEX('Group Stage'!$I$1:$I$200,MATCH(L11,'Group Stage'!$A$1:$A$200,0)),0) -> 0 | O11: =IF(AND('Knockout & Winner'!$G$59<>"",'Knockout & Winner'!$G$59=L11),25,IF(AND('Knockout & Winner'!$G$55<>"",'Knockout & Winner'!$G$55=L11),15,IF(OR(AND('Knockout & Winner'!$B$59<>"",'Knockout & Winner'!$B$59=L11),AND('Knockout & Winner'!$E$59<>"",'Knockout & Winner'!$E$59=L11)),18,IF(COUNTIF('Knockout & Winner'!$G$50:$G$51,L11)>0,12,IF(COUNTIF('Knockout & Winner'!$G$43:$G$46,L11)>0,8,IF(COUNTIF('Knockout & Winner'!$G$32:$G$39,L11)>0,5,IF(COUNTIF('Knockout & Winner'!$G$13:$G$28,L11)>0,3,0))))))) -> 0 | P11: =N11+O11 -> 0 | Q11: =IF(OR(COUNTIF('Knockout & Winner'!$G$13:$G$28,L11)>0,COUNTIF('Knockout & Winner'!$G$32:$G$39,L11)>0,COUNTIF('Knockout & Winner'!$G$43:$G$46,L11)>0,COUNTIF('Knockout & Winner'!$G$50:$G$51,L11)>0,'Knockout & Winner'!$G$55=L11,'Knockout & Winner'!$G$59=L11),"Yes","")
A12: =RANK(E12,E$10:E$17,0) -> 1 | B12: Craig | C12: =SUMIF(M$10:M$57,B12,N$10:N$57) -> 0 | D12: =SUMIF(M$10:M$57,B12,O$10:O$57) -> 0 | E12: =SUMIF(M$10:M$57,B12,P$10:P$57) -> 0 | F12: =COUNTIFS(M$10:M$57,B12,Q$10:Q$57,"Yes") -> 0 | G12: =IFERROR(INDEX(L$10:L$57,MATCH(_xludf.MAXIFS(P$10:P$57,M$10:M$57,B12,Q$10:Q$57,"Yes"),P$10:P$57,0)),"—") -> — | L12: South Africa | M12: =IFERROR(VLOOKUP(L12,'Participating Teams'!$B$4:$F$51,5,FALSE),"") -> 0 | N12: =IFERROR(INDEX('Group Stage'!$I$1:$I$200,MATCH(L12,'Group Stage'!$A$1:$A$200,0)),0) -> 0 | O12: =IF(AND('Knockout & Winner'!$G$59<>"",'Knockout & Winner'!$G$59=L12),25,IF(AND('Knockout & Winner'!$G$55<>"",'Knockout & Winner'!$G$55=L12),15,IF(OR(AND('Knockout & Winner'!$B$59<>"",'Knockout & Winner'!$B$59=L12),AND('Knockout & Winner'!$E$59<>"",'Knockout & Winner'!$E$59=L12)),18,IF(COUNTIF('Knockout & Winner'!$G$50:$G$51,L12)>0,12,IF(COUNTIF('Knockout & Winner'!$G$43:$G$46,L12)>0,8,IF(COUNTIF('Knockout & Winner'!$G$32:$G$39,L12)>0,5,IF(COUNTIF('Knockout & Winner'!$G$13:$G$28,L12)>0,3,0))))))) -> 0 | P12: =N12+O12 -> 0 | Q12: =IF(OR(COUNTIF('Knockout & Winner'!$G$13:$G$28,L12)>0,COUNTIF('Knockout & Winner'!$G$32:$G$39,L12)>0,COUNTIF('Knockout & Winner'!$G$43:$G$46,L12)>0,COUNTIF('Knockout & Winner'!$G$50:$G$51,L12)>0,'Knockout & Winner'!$G$55=L12,'Knockout & Winner'!$G$59=L12),"Yes","")
A13: =RANK(E13,E$10:E$17,0) -> 1 | B13: Anna | C13: =SUMIF(M$10:M$57,B13,N$10:N$57) -> 0 | D13: =SUMIF(M$10:M$57,B13,O$10:O$57) -> 0 | E13: =SUMIF(M$10:M$57,B13,P$10:P$57) -> 0 | F13: =COUNTIFS(M$10:M$57,B13,Q$10:Q$57,"Yes") -> 0 | G13: =IFERROR(INDEX(L$10:L$57,MATCH(_xludf.MAXIFS(P$10:P$57,M$10:M$57,B13,Q$10:Q$57,"Yes"),P$10:P$57,0)),"—") -> — | L13: Czechia | M13: =IFERROR(VLOOKUP(L13,'Participating Teams'!$B$4:$F$51,5,FALSE),"") -> 0 | N13: =IFERROR(INDEX('Group Stage'!$I$1:$I$200,MATCH(L13,'Group Stage'!$A$1:$A$200,0)),0) -> 0 | O13: =IF(AND('Knockout & Winner'!$G$59<>"",'Knockout & Winner'!$G$59=L13),25,IF(AND('Knockout & Winner'!$G$55<>"",'Knockout & Winner'!$G$55=L13),15,IF(OR(AND('Knockout & Winner'!$B$59<>"",'Knockout & Winner'!$B$59=L13),AND('Knockout & Winner'!$E$59<>"",'Knockout & Winner'!$E$59=L13)),18,IF(COUNTIF('Knockout & Winner'!$G$50:$G$51,L13)>0,12,IF(COUNTIF('Knockout & Winner'!$G$43:$G$46,L13)>0,8,IF(COUNTIF('Knockout & Winner'!$G$32:$G$39,L13)>0,5,IF(COUNTIF('Knockout & Winner'!$G$13:$G$28,L13)>0,3,0))))))) -> 0 | P13: =N13+O13 -> 0 | Q13: =IF(OR(COUNTIF('Knockout & Winner'!$G$13:$G$28,L13)>0,COUNTIF('Knockout & Winner'!$G$32:$G$39,L13)>0,COUNTIF('Knockout & Winner'!$G$43:$G$46,L13)>0,COUNTIF('Knockout & Winner'!$G$50:$G$51,L13)>0,'Knockout & Winner'!$G$55=L13,'Knockout & Winner'!$G$59=L13),"Yes","")
A14: =RANK(E14,E$10:E$17,0) -> 1 | B14: Brooke | C14: =SUMIF(M$10:M$57,B14,N$10:N$57) -> 0 | D14: =SUMIF(M$10:M$57,B14,O$10:O$57) -> 0 | E14: =SUMIF(M$10:M$57,B14,P$10:P$57) -> 0 | F14: =COUNTIFS(M$10:M$57,B14,Q$10:Q$57,"Yes") -> 0 | G14: =IFERROR(INDEX(L$10:L$57,MATCH(_xludf.MAXIFS(P$10:P$57,M$10:M$57,B14,Q$10:Q$57,"Yes"),P$10:P$57,0)),"—") -> — | L14: Canada | M14: =IFERROR(VLOOKUP(L14,'Participating Teams'!$B$4:$F$51,5,FALSE),"") -> 0 | N14: =IFERROR(INDEX('Group Stage'!$I$1:$I$200,MATCH(L14,'Group Stage'!$A$1:$A$200,0)),0) -> 0 | O14: =IF(AND('Knockout & Winner'!$G$59<>"",'Knockout & Winner'!$G$59=L14),25,IF(AND('Knockout & Winner'!$G$55<>"",'Knockout & Winner'!$G$55=L14),15,IF(OR(AND('Knockout & Winner'!$B$59<>"",'Knockout & Winner'!$B$59=L14),AND('Knockout & Winner'!$E$59<>"",'Knockout & Winner'!$E$59=L14)),18,IF(COUNTIF('Knockout & Winner'!$G$50:$G$51,L14)>0,12,IF(COUNTIF('Knockout & Winner'!$G$43:$G$46,L14)>0,8,IF(COUNTIF('Knockout & Winner'!$G$32:$G$39,L14)>0,5,IF(COUNTIF('Knockout & Winner'!$G$13:$G$28,L14)>0,3,0))))))) -> 0 | P14: =N14+O14 -> 0 | Q14: =IF(OR(COUNTIF('Knockout & Winner'!$G$13:$G$28,L14)>0,COUNTIF('Knockout & Winner'!$G$32:$G$39,L14)>0,COUNTIF('Knockout & Winner'!$G$43:$G$46,L14)>0,COUNTIF('Knockout & Winner'!$G$50:$G$51,L14)>0,'Knockout & Winner'!$G$55=L14,'Knockout & Winner'!$G$59=L14),"Yes","")
A15: =RANK(E15,E$10:E$17,0) -> 1 | B15: Lachlan | C15: =SUMIF(M$10:M$57,B15,N$10:N$57) -> 0 | D15: =SUMIF(M$10:M$57,B15,O$10:O$57) -> 0 | E15: =SUMIF(M$10:M$57,B15,P$10:P$57) -> 0 | F15: =COUNTIFS(M$10:M$57,B15,Q$10:Q$57,"Yes") -> 0 | G15: =IFERROR(INDEX(L$10:L$57,MATCH(_xludf.MAXIFS(P$10:P$57,M$10:M$57,B15,Q$10:Q$57,"Yes"),P$10:P$57,0)),"—") -> — | L15: Switzerland | M15: =IFERROR(VLOOKUP(L15,'Participating Teams'!$B$4:$F$51,5,FALSE),"") -> 0 | N15: =IFERROR(INDEX('Group Stage'!$I$1:$I$200,MATCH(L15,'Group Stage'!$A$1:$A$200,0)),0) -> 0 | O15: =IF(AND('Knockout & Winner'!$G$59<>"",'Knockout & Winner'!$G$59=L15),25,IF(AND('Knockout & Winner'!$G$55<>"",'Knockout & Winner'!$G$55=L15),15,IF(OR(AND('Knockout & Winner'!$B$59<>"",'Knockout & Winner'!$B$59=L15),AND('Knockout & Winner'!$E$59<>"",'Knockout & Winner'!$E$59=L15)),18,IF(COUNTIF('Knockout & Winner'!$G$50:$G$51,L15)>0,12,IF(COUNTIF('Knockout & Winner'!$G$43:$G$46,L15)>0,8,IF(COUNTIF('Knockout & Winner'!$G$32:$G$39,L15)>0,5,IF(COUNTIF('Knockout & Winner'!$G$13:$G$28,L15)>0,3,0))))))) -> 0 | P15: =N15+O15 -> 0 | Q15: =IF(OR(COUNTIF('Knockout & Winner'!$G$13:$G$28,L15)>0,COUNTIF('Knockout & Winner'!$G$32:$G$39,L15)>0,COUNTIF('Knockout & Winner'!$G$43:$G$46,L15)>0,COUNTIF('Knockout & Winner'!$G$50:$G$51,L15)>0,'Knockout & Winner'!$G$55=L15,'Knockout & Winner'!$G$59=L15),"Yes","")
A16: =RANK(E16,E$10:E$17,0) -> 1 | B16: Sienna | C16: =SUMIF(M$10:M$57,B16,N$10:N$57) -> 0 | D16: =SUMIF(M$10:M$57,B16,O$10:O$57) -> 0 | E16: =SUMIF(M$10:M$57,B16,P$10:P$57) -> 0 | F16: =COUNTIFS(M$10:M$57,B16,Q$10:Q$57,"Yes") -> 0 | G16: =IFERROR(INDEX(L$10:L$57,MATCH(_xludf.MAXIFS(P$10:P$57,M$10:M$57,B16,Q$10:Q$57,"Yes"),P$10:P$57,0)),"—") -> — | L16: Qatar | M16: =IFERROR(VLOOKUP(L16,'Participating Teams'!$B$4:$F$51,5,FALSE),"") -> 0 | N16: =IFERROR(INDEX('Group Stage'!$I$1:$I$200,MATCH(L16,'Group Stage'!$A$1:$A$200,0)),0) -> 0 | O16: =IF(AND('Knockout & Winner'!$G$59<>"",'Knockout & Winner'!$G$59=L16),25,IF(AND('Knockout & Winner'!$G$55<>"",'Knockout & Winner'!$G$55=L16),15,IF(OR(AND('Knockout & Winner'!$B$59<>"",'Knockout & Winner'!$B$59=L16),AND('Knockout & Winner'!$E$59<>"",'Knockout & Winner'!$E$59=L16)),18,IF(COUNTIF('Knockout & Winner'!$G$50:$G$51,L16)>0,12,IF(COUNTIF('Knockout & Winner'!$G$43:$G$46,L16)>0,8,IF(COUNTIF('Knockout & Winner'!$G$32:$G$39,L16)>0,5,IF(COUNTIF('Knockout & Winner'!$G$13:$G$28,L16)>0,3,0))))))) -> 0 | P16: =N16+O16 -> 0 | Q16: =IF(OR(COUNTIF('Knockout & Winner'!$G$13:$G$28,L16)>0,COUNTIF('Knockout & Winner'!$G$32:$G$39,L16)>0,COUNTIF('Knockout & Winner'!$G$43:$G$46,L16)>0,COUNTIF('Knockout & Winner'!$G$50:$G$51,L16)>0,'Knockout & Winner'!$G$55=L16,'Knockout & Winner'!$G$59=L16),"Yes","")
A17: =RANK(E17,E$10:E$17,0) -> 1 | B17: Brent | C17: =SUMIF(M$10:M$57,B17,N$10:N$57) -> 0 | D17: =SUMIF(M$10:M$57,B17,O$10:O$57) -> 0 | E17: =SUMIF(M$10:M$57,B17,P$10:P$57) -> 0 | F17: =COUNTIFS(M$10:M$57,B17,Q$10:Q$57,"Yes") -> 0 | G17: =IFERROR(INDEX(L$10:L$57,MATCH(_xludf.MAXIFS(P$10:P$57,M$10:M$57,B17,Q$10:Q$57,"Yes"),P$10:P$57,0)),"—") -> — | L17: Bosnia and Herzegovina | M17: =IFERROR(VLOOKUP(L17,'Participating Teams'!$B$4:$F$51,5,FALSE),"") -> 0 | N17: =IFERROR(INDEX('Group Stage'!$I$1:$I$200,MATCH(L17,'Group Stage'!$A$1:$A$200,0)),0) -> 0 | O17: =IF(AND('Knockout & Winner'!$G$59<>"",'Knockout & Winner'!$G$59=L17),25,IF(AND('Knockout & Winner'!$G$55<>"",'Knockout & Winner'!$G$55=L17),15,IF(OR(AND('Knockout & Winner'!$B$59<>"",'Knockout & Winner'!$B$59=L17),AND('Knockout & Winner'!$E$59<>"",'Knockout & Winner'!$E$59=L17)),18,IF(COUNTIF('Knockout & Winner'!$G$50:$G$51,L17)>0,12,IF(COUNTIF('Knockout & Winner'!$G$43:$G$46,L17)>0,8,IF(COUNTIF('Knockout & Winner'!$G$32:$G$39,L17)>0,5,IF(COUNTIF('Knockout & Winner'!$G$13:$G$28,L17)>0,3,0))))))) -> 0 | P17: =N17+O17 -> 0 | Q17: =IF(OR(COUNTIF('Knockout & Winner'!$G$13:$G$28,L17)>0,COUNTIF('Knockout & Winner'!$G$32:$G$39,L17)>0,COUNTIF('Knockout & Winner'!$G$43:$G$46,L17)>0,COUNTIF('Knockout & Winner'!$G$50:$G$51,L17)>0,'Knockout & Winner'!$G$55=L17,'Knockout & Winner'!$G$59=L17),"Yes","")
L18: Brazil | M18: =IFERROR(VLOOKUP(L18,'Participating Teams'!$B$4:$F$51,5,FALSE),"") -> 0 | N18: =IFERROR(INDEX('Group Stage'!$I$1:$I$200,MATCH(L18,'Group Stage'!$A$1:$A$200,0)),0) -> 0 | O18: =IF(AND('Knockout & Winner'!$G$59<>"",'Knockout & Winner'!$G$59=L18),25,IF(AND('Knockout & Winner'!$G$55<>"",'Knockout & Winner'!$G$55=L18),15,IF(OR(AND('Knockout & Winner'!$B$59<>"",'Knockout & Winner'!$B$59=L18),AND('Knockout & Winner'!$E$59<>"",'Knockout & Winner'!$E$59=L18)),18,IF(COUNTIF('Knockout & Winner'!$G$50:$G$51,L18)>0,12,IF(COUNTIF('Knockout & Winner'!$G$43:$G$46,L18)>0,8,IF(COUNTIF('Knockout & Winner'!$G$32:$G$39,L18)>0,5,IF(COUNTIF('Knockout & Winner'!$G$13:$G$28,L18)>0,3,0))))))) -> 0 | P18: =N18+O18 -> 0 | Q18: =IF(OR(COUNTIF('Knockout & Winner'!$G$13:$G$28,L18)>0,COUNTIF('Knockout & Winner'!$G$32:$G$39,L18)>0,COUNTIF('Knockout & Winner'!$G$43:$G$46,L18)>0,COUNTIF('Knockout & Winner'!$G$50:$G$51,L18)>0,'Knockout & Winner'!$G$55=L18,'Knockout & Winner'!$G$59=L18),"Yes","")
A19: TEAM SCORES | L19: Morocco | M19: =IFERROR(VLOOKUP(L19,'Participating Teams'!$B$4:$F$51,5,FALSE),"") -> 0 | N19: =IFERROR(INDEX('Group Stage'!$I$1:$I$200,MATCH(L19,'Group Stage'!$A$1:$A$200,0)),0) -> 0 | O19: =IF(AND('Knockout & Winner'!$G$59<>"",'Knockout & Winner'!$G$59=L19),25,IF(AND('Knockout & Winner'!$G$55<>"",'Knockout & Winner'!$G$55=L19),15,IF(OR(AND('Knockout & Winner'!$B$59<>"",'Knockout & Winner'!$B$59=L19),AND('Knockout & Winner'!$E$59<>"",'Knockout & Winner'!$E$59=L19)),18,IF(COUNTIF('Knockout & Winner'!$G$50:$G$51,L19)>0,12,IF(COUNTIF('Knockout & Winner'!$G$43:$G$46,L19)>0,8,IF(COUNTIF('Knockout & Winner'!$G$32:$G$39,L19)>0,5,IF(COUNTIF('Knockout & Winner'!$G$13:$G$28,L19)>0,3,0))))))) -> 0 | P19: =N19+O19 -> 0 | Q19: =IF(OR(COUNTIF('Knockout & Winner'!$G$13:$G$28,L19)>0,COUNTIF('Knockout & Winner'!$G$32:$G$39,L19)>0,COUNTIF('Knockout & Winner'!$G$43:$G$46,L19)>0,COUNTIF('Knockout & Winner'!$G$50:$G$51,L19)>0,'Knockout & Winner'!$G$55=L19,'Knockout & Winner'!$G$59=L19),"Yes","")
A20: Team | B20: Member | C20: Group | D20: Group Pts | E20: Knockout Stage | F20: Knockout Pts | G20: Total | L20: Scotland | M20: =IFERROR(VLOOKUP(L20,'Participating Teams'!$B$4:$F$51,5,FALSE),"") -> 0 | N20: =IFERROR(INDEX('Group Stage'!$I$1:$I$200,MATCH(L20,'Group Stage'!$A$1:$A$200,0)),0) -> 0 | O20: =IF(AND('Knockout & Winner'!$G$59<>"",'Knockout & Winner'!$G$59=L20),25,IF(AND('Knockout & Winner'!$G$55<>"",'Knockout & Winner'!$G$55=L20),15,IF(OR(AND('Knockout & Winner'!$B$59<>"",'Knockout & Winner'!$B$59=L20),AND('Knockout & Winner'!$E$59<>"",'Knockout & Winner'!$E$59=L20)),18,IF(COUNTIF('Knockout & Winner'!$G$50:$G$51,L20)>0,12,IF(COUNTIF('Knockout & Winner'!$G$43:$G$46,L20)>0,8,IF(COUNTIF('Knockout & Winner'!$G$32:$G$39,L20)>0,5,IF(COUNTIF('Knockout & Winner'!$G$13:$G$28,L20)>0,3,0))))))) -> 0 | P20: =N20+O20 -> 0 | Q20: =IF(OR(COUNTIF('Knockout & Winner'!$G$13:$G$28,L20)>0,COUNTIF('Knockout & Winner'!$G$32:$G$39,L20)>0,COUNTIF('Knockout & Winner'!$G$43:$G$46,L20)>0,COUNTIF('Knockout & Winner'!$G$50:$G$51,L20)>0,'Knockout & Winner'!$G$55=L20,'Knockout & Winner'!$G$59=L20),"Yes","")
A21: =L10 -> Mexico | B21: =M10 -> 0 | C21: A | D21: =N10 -> 0 | E21: =IF(O10=25,"Champion",IF(OR('Knockout & Winner'!$B$59=L10,'Knockout & Winner'!$E$59=L10),"Finalist",IF(O10=15,"3rd Place",IF(O10=12,"Semi-final",IF(O10=8,"Quarter-final",IF(O10=5,"Round of 16",IF(O10=3,"Round of 32","—"))))))) -> — | F21: =O10 -> 0 | G21: =P10 -> 0 | L21: Haiti | M21: =IFERROR(VLOOKUP(L21,'Participating Teams'!$B$4:$F$51,5,FALSE),"") -> 0 | N21: =IFERROR(INDEX('Group Stage'!$I$1:$I$200,MATCH(L21,'Group Stage'!$A$1:$A$200,0)),0) -> 0 | O21: =IF(AND('Knockout & Winner'!$G$59<>"",'Knockout & Winner'!$G$59=L21),25,IF(AND('Knockout & Winner'!$G$55<>"",'Knockout & Winner'!$G$55=L21),15,IF(OR(AND('Knockout & Winner'!$B$59<>"",'Knockout & Winner'!$B$59=L21),AND('Knockout & Winner'!$E$59<>"",'Knockout & Winner'!$E$59=L21)),18,IF(COUNTIF('Knockout & Winner'!$G$50:$G$51,L21)>0,12,IF(COUNTIF('Knockout & Winner'!$G$43:$G$46,L21)>0,8,IF(COUNTIF('Knockout & Winner'!$G$32:$G$39,L21)>0,5,IF(COUNTIF('Knockout & Winner'!$G$13:$G$28,L21)>0,3,0))))))) -> 0 | P21: =N21+O21 -> 0 | Q21: =IF(OR(COUNTIF('Knockout & Winner'!$G$13:$G$28,L21)>0,COUNTIF('Knockout & Winner'!$G$32:$G$39,L21)>0,COUNTIF('Knockout & Winner'!$G$43:$G$46,L21)>0,COUNTIF('Knockout & Winner'!$G$50:$G$51,L21)>0,'Knockout & Winner'!$G$55=L21,'Knockout & Winner'!$G$59=L21),"Yes","")
A22: =L11 -> South Korea | B22: =M11 -> 0 | C22: A | D22: =N11 -> 0 | E22: =IF(O11=25,"Champion",IF(OR('Knockout & Winner'!$B$59=L11,'Knockout & Winner'!$E$59=L11),"Finalist",IF(O11=15,"3rd Place",IF(O11=12,"Semi-final",IF(O11=8,"Quarter-final",IF(O11=5,"Round of 16",IF(O11=3,"Round of 32","—"))))))) -> — | F22: =O11 -> 0 | G22: =P11 -> 0 | L22: United States | M22: =IFERROR(VLOOKUP(L22,'Participating Teams'!$B$4:$F$51,5,FALSE),"") -> 0 | N22: =IFERROR(INDEX('Group Stage'!$I$1:$I$200,MATCH(L22,'Group Stage'!$A$1:$A$200,0)),0) -> 0 | O22: =IF(AND('Knockout & Winner'!$G$59<>"",'Knockout & Winner'!$G$59=L22),25,IF(AND('Knockout & Winner'!$G$55<>"",'Knockout & Winner'!$G$55=L22),15,IF(OR(AND('Knockout & Winner'!$B$59<>"",'Knockout & Winner'!$B$59=L22),AND('Knockout & Winner'!$E$59<>"",'Knockout & Winner'!$E$59=L22)),18,IF(COUNTIF('Knockout & Winner'!$G$50:$G$51,L22)>0,12,IF(COUNTIF('Knockout & Winner'!$G$43:$G$46,L22)>0,8,IF(COUNTIF('Knockout & Winner'!$G$32:$G$39,L22)>0,5,IF(COUNTIF('Knockout & Winner'!$G$13:$G$28,L22)>0,3,0))))))) -> 0 | P22: =N22+O22 -> 0 | Q22: =IF(OR(COUNTIF('Knockout & Winner'!$G$13:$G$28,L22)>0,COUNTIF('Knockout & Winner'!$G$32:$G$39,L22)>0,COUNTIF('Knockout & Winner'!$G$43:$G$46,L22)>0,COUNTIF('Knockout & Winner'!$G$50:$G$51,L22)>0,'Knockout & Winner'!$G$55=L22,'Knockout & Winner'!$G$59=L22),"Yes","")
A23: =L12 -> South Africa | B23: =M12 -> 0 | C23: A | D23: =N12 -> 0 | E23: =IF(O12=25,"Champion",IF(OR('Knockout & Winner'!$B$59=L12,'Knockout & Winner'!$E$59=L12),"Finalist",IF(O12=15,"3rd Place",IF(O12=12,"Semi-final",IF(O12=8,"Quarter-final",IF(O12=5,"Round of 16",IF(O12=3,"Round of 32","—"))))))) -> — | F23: =O12 -> 0 | G23: =P12 -> 0 | L23: Paraguay | M23: =IFERROR(VLOOKUP(L23,'Participating Teams'!$B$4:$F$51,5,FALSE),"") -> 0 | N23: =IFERROR(INDEX('Group Stage'!$I$1:$I$200,MATCH(L23,'Group Stage'!$A$1:$A$200,0)),0) -> 0 | O23: =IF(AND('Knockout & Winner'!$G$59<>"",'Knockout & Winner'!$G$59=L23),25,IF(AND('Knockout & Winner'!$G$55<>"",'Knockout & Winner'!$G$55=L23),15,IF(OR(AND('Knockout & Winner'!$B$59<>"",'Knockout & Winner'!$B$59=L23),AND('Knockout & Winner'!$E$59<>"",'Knockout & Winner'!$E$59=L23)),18,IF(COUNTIF('Knockout & Winner'!$G$50:$G$51,L23)>0,12,IF(COUNTIF('Knockout & Winner'!$G$43:$G$46,L23)>0,8,IF(COUNTIF('Knockout & Winner'!$G$32:$G$39,L23)>0,5,IF(COUNTIF('Knockout & Winner'!$G$13:$G$28,L23)>0,3,0))))))) -> 0 | P23: =N23+O23 -> 0 | Q23: =IF(OR(COUNTIF('Knockout & Winner'!$G$13:$G$28,L23)>0,COUNTIF('Knockout & Winner'!$G$32:$G$39,L23)>0,COUNTIF('Knockout & Winner'!$G$43:$G$46,L23)>0,COUNTIF('Knockout & Winner'!$G$50:$G$51,L23)>0,'Knockout & Winner'!$G$55=L23,'Knockout & Winner'!$G$59=L23),"Yes","")
A24: =L13 -> Czechia | B24: =M13 -> 0 | C24: A | D24: =N13 -> 0 | E24: =IF(O13=25,"Champion",IF(OR('Knockout & Winner'!$B$59=L13,'Knockout & Winner'!$E$59=L13),"Finalist",IF(O13=15,"3rd Place",IF(O13=12,"Semi-final",IF(O13=8,"Quarter-final",IF(O13=5,"Round of 16",IF(O13=3,"Round of 32","—"))))))) -> — | F24: =O13 -> 0 | G24: =P13 -> 0 | L24: Australia | M24: =IFERROR(VLOOKUP(L24,'Participating Teams'!$B$4:$F$51,5,FALSE),"") -> 0 | N24: =IFERROR(INDEX('Group Stage'!$I$1:$I$200,MATCH(L24,'Group Stage'!$A$1:$A$200,0)),0) -> 0 | O24: =IF(AND('Knockout & Winner'!$G$59<>"",'Knockout & Winner'!$G$59=L24),25,IF(AND('Knockout & Winner'!$G$55<>"",'Knockout & Winner'!$G$55=L24),15,IF(OR(AND('Knockout & Winner'!$B$59<>"",'Knockout & Winner'!$B$59=L24),AND('Knockout & Winner'!$E$59<>"",'Knockout & Winner'!$E$59=L24)),18,IF(COUNTIF('Knockout & Winner'!$G$50:$G$51,L24)>0,12,IF(COUNTIF('Knockout & Winner'!$G$43:$G$46,L24)>0,8,IF(COUNTIF('Knockout & Winner'!$G$32:$G$39,L24)>0,5,IF(COUNTIF('Knockout & Winner'!$G$13:$G$28,L24)>0,3,0))))))) -> 0 | P24: =N24+O24 -> 0 | Q24: =IF(OR(COUNTIF('Knockout & Winner'!$G$13:$G$28,L24)>0,COUNTIF('Knockout & Winner'!$G$32:$G$39,L24)>0,COUNTIF('Knockout & Winner'!$G$43:$G$46,L24)>0,COUNTIF('Knockout & Winner'!$G$50:$G$51,L24)>0,'Knockout & Winner'!$G$55=L24,'Knockout & Winner'!$G$59=L24),"Yes","")
A25: =L14 -> Canada | B25: =M14 -> 0 | C25: B | D25: =N14 -> 0 | E25: =IF(O14=25,"Champion",IF(OR('Knockout & Winner'!$B$59=L14,'Knockout & Winner'!$E$59=L14),"Finalist",IF(O14=15,"3rd Place",IF(O14=12,"Semi-final",IF(O14=8,"Quarter-final",IF(O14=5,"Round of 16",IF(O14=3,"Round of 32","—"))))))) -> — | F25: =O14 -> 0 | G25: =P14 -> 0 | L25: Türkiye | M25: =IFERROR(VLOOKUP(L25,'Participating Teams'!$B$4:$F$51,5,FALSE),"") -> 0 | N25: =IFERROR(INDEX('Group Stage'!$I$1:$I$200,MATCH(L25,'Group Stage'!$A$1:$A$200,0)),0) -> 0 | O25: =IF(AND('Knockout & Winner'!$G$59<>"",'Knockout & Winner'!$G$59=L25),25,IF(AND('Knockout & Winner'!$G$55<>"",'Knockout & Winner'!$G$55=L25),15,IF(OR(AND('Knockout & Winner'!$B$59<>"",'Knockout & Winner'!$B$59=L25),AND('Knockout & Winner'!$E$59<>"",'Knockout & Winner'!$E$59=L25)),18,IF(COUNTIF('Knockout & Winner'!$G$50:$G$51,L25)>0,12,IF(COUNTIF('Knockout & Winner'!$G$43:$G$46,L25)>0,8,IF(COUNTIF('Knockout & Winner'!$G$32:$G$39,L25)>0,5,IF(COUNTIF('Knockout & Winner'!$G$13:$G$28,L25)>0,3,0))))))) -> 0 | P25: =N25+O25 -> 0 | Q25: =IF(OR(COUNTIF('Knockout & Winner'!$G$13:$G$28,L25)>0,COUNTIF('Knockout & Winner'!$G$32:$G$39,L25)>0,COUNTIF('Knockout & Winner'!$G$43:$G$46,L25)>0,COUNTIF('Knockout & Winner'!$G$50:$G$51,L25)>0,'Knockout & Winner'!$G$55=L25,'Knockout & Winner'!$G$59=L25),"Yes","")
A26: =L15 -> Switzerland | B26: =M15 -> 0 | C26: B | D26: =N15 -> 0 | E26: =IF(O15=25,"Champion",IF(OR('Knockout & Winner'!$B$59=L15,'Knockout & Winner'!$E$59=L15),"Finalist",IF(O15=15,"3rd Place",IF(O15=12,"Semi-final",IF(O15=8,"Quarter-final",IF(O15=5,"Round of 16",IF(O15=3,"Round of 32","—"))))))) -> — | F26: =O15 -> 0 | G26: =P15 -> 0 | L26: Germany | M26: =IFERROR(VLOOKUP(L26,'Participating Teams'!$B$4:$F$51,5,FALSE),"") -> 0 | N26: =IFERROR(INDEX('Group Stage'!$I$1:$I$200,MATCH(L26,'Group Stage'!$A$1:$A$200,0)),0) -> 0 | O26: =IF(AND('Knockout & Winner'!$G$59<>"",'Knockout & Winner'!$G$59=L26),25,IF(AND('Knockout & Winner'!$G$55<>"",'Knockout & Winner'!$G$55=L26),15,IF(OR(AND('Knockout & Winner'!$B$59<>"",'Knockout & Winner'!$B$59=L26),AND('Knockout & Winner'!$E$59<>"",'Knockout & Winner'!$E$59=L26)),18,IF(COUNTIF('Knockout & Winner'!$G$50:$G$51,L26)>0,12,IF(COUNTIF('Knockout & Winner'!$G$43:$G$46,L26)>0,8,IF(COUNTIF('Knockout & Winner'!$G$32:$G$39,L26)>0,5,IF(COUNTIF('Knockout & Winner'!$G$13:$G$28,L26)>0,3,0))))))) -> 0 | P26: =N26+O26 -> 0 | Q26: =IF(OR(COUNTIF('Knockout & Winner'!$G$13:$G$28,L26)>0,COUNTIF('Knockout & Winner'!$G$32:$G$39,L26)>0,COUNTIF('Knockout & Winner'!$G$43:$G$46,L26)>0,COUNTIF('Knockout & Winner'!$G$50:$G$51,L26)>0,'Knockout & Winner'!$G$55=L26,'Knockout & Winner'!$G$59=L26),"Yes","")
A27: =L16 -> Qatar | B27: =M16 -> 0 | C27: B | D27: =N16 -> 0 | E27: =IF(O16=25,"Champion",IF(OR('Knockout & Winner'!$B$59=L16,'Knockout & Winner'!$E$59=L16),"Finalist",IF(O16=15,"3rd Place",IF(O16=12,"Semi-final",IF(O16=8,"Quarter-final",IF(O16=5,"Round of 16",IF(O16=3,"Round of 32","—"))))))) -> — | F27: =O16 -> 0 | G27: =P16 -> 0 | L27: Ecuador | M27: =IFERROR(VLOOKUP(L27,'Participating Teams'!$B$4:$F$51,5,FALSE),"") -> 0 | N27: =IFERROR(INDEX('Group Stage'!$I$1:$I$200,MATCH(L27,'Group Stage'!$A$1:$A$200,0)),0) -> 0 | O27: =IF(AND('Knockout & Winner'!$G$59<>"",'Knockout & Winner'!$G$59=L27),25,IF(AND('Knockout & Winner'!$G$55<>"",'Knockout & Winner'!$G$55=L27),15,IF(OR(AND('Knockout & Winner'!$B$59<>"",'Knockout & Winner'!$B$59=L27),AND('Knockout & Winner'!$E$59<>"",'Knockout & Winner'!$E$59=L27)),18,IF(COUNTIF('Knockout & Winner'!$G$50:$G$51,L27)>0,12,IF(COUNTIF('Knockout & Winner'!$G$43:$G$46,L27)>0,8,IF(COUNTIF('Knockout & Winner'!$G$32:$G$39,L27)>0,5,IF(COUNTIF('Knockout & Winner'!$G$13:$G$28,L27)>0,3,0))))))) -> 0 | P27: =N27+O27 -> 0 | Q27: =IF(OR(COUNTIF('Knockout & Winner'!$G$13:$G$28,L27)>0,COUNTIF('Knockout & Winner'!$G$32:$G$39,L27)>0,COUNTIF('Knockout & Winner'!$G$43:$G$46,L27)>0,COUNTIF('Knockout & Winner'!$G$50:$G$51,L27)>0,'Knockout & Winner'!$G$55=L27,'Knockout & Winner'!$G$59=L27),"Yes","")
A28: =L17 -> Bosnia and Herzegovina | B28: =M17 -> 0 | C28: B | D28: =N17 -> 0 | E28: =IF(O17=25,"Champion",IF(OR('Knockout & Winner'!$B$59=L17,'Knockout & Winner'!$E$59=L17),"Finalist",IF(O17=15,"3rd Place",IF(O17=12,"Semi-final",IF(O17=8,"Quarter-final",IF(O17=5,"Round of 16",IF(O17=3,"Round of 32","—"))))))) -> — | F28: =O17 -> 0 | G28: =P17 -> 0 | L28: Côte d'Ivoire | M28: =IFERROR(VLOOKUP(L28,'Participating Teams'!$B$4:$F$51,5,FALSE),"") -> 0 | N28: =IFERROR(INDEX('Group Stage'!$I$1:$I$200,MATCH(L28,'Group Stage'!$A$1:$A$200,0)),0) -> 0 | O28: =IF(AND('Knockout & Winner'!$G$59<>"",'Knockout & Winner'!$G$59=L28),25,IF(AND('Knockout & Winner'!$G$55<>"",'Knockout & Winner'!$G$55=L28),15,IF(OR(AND('Knockout & Winner'!$B$59<>"",'Knockout & Winner'!$B$59=L28),AND('Knockout & Winner'!$E$59<>"",'Knockout & Winner'!$E$59=L28)),18,IF(COUNTIF('Knockout & Winner'!$G$50:$G$51,L28)>0,12,IF(COUNTIF('Knockout & Winner'!$G$43:$G$46,L28)>0,8,IF(COUNTIF('Knockout & Winner'!$G$32:$G$39,L28)>0,5,IF(COUNTIF('Knockout & Winner'!$G$13:$G$28,L28)>0,3,0))))))) -> 0 | P28: =N28+O28 -> 0 | Q28: =IF(OR(COUNTIF('Knockout & Winner'!$G$13:$G$28,L28)>0,COUNTIF('Knockout & Winner'!$G$32:$G$39,L28)>0,COUNTIF('Knockout & Winner'!$G$43:$G$46,L28)>0,COUNTIF('Knockout & Winner'!$G$50:$G$51,L28)>0,'Knockout & Winner'!$G$55=L28,'Knockout & Winner'!$G$59=L28),"Yes","")
A29: =L18 -> Brazil | B29: =M18 -> 0 | C29: C | D29: =N18 -> 0 | E29: =IF(O18=25,"Champion",IF(OR('Knockout & Winner'!$B$59=L18,'Knockout & Winner'!$E$59=L18),"Finalist",IF(O18=15,"3rd Place",IF(O18=12,"Semi-final",IF(O18=8,"Quarter-final",IF(O18=5,"Round of 16",IF(O18=3,"Round of 32","—"))))))) -> — | F29: =O18 -> 0 | G29: =P18 -> 0 | L29: Curaçao | M29: =IFERROR(VLOOKUP(L29,'Participating Teams'!$B$4:$F$51,5,FALSE),"") -> 0 | N29: =IFERROR(INDEX('Group Stage'!$I$1:$I$200,MATCH(L29,'Group Stage'!$A$1:$A$200,0)),0) -> 0 | O29: =IF(AND('Knockout & Winner'!$G$59<>"",'Knockout & Winner'!$G$59=L29),25,IF(AND('Knockout & Winner'!$G$55<>"",'Knockout & Winner'!$G$55=L29),15,IF(OR(AND('Knockout & Winner'!$B$59<>"",'Knockout & Winner'!$B$59=L29),AND('Knockout & Winner'!$E$59<>"",'Knockout & Winner'!$E$59=L29)),18,IF(COUNTIF('Knockout & Winner'!$G$50:$G$51,L29)>0,12,IF(COUNTIF('Knockout & Winner'!$G$43:$G$46,L29)>0,8,IF(COUNTIF('Knockout & Winner'!$G$32:$G$39,L29)>0,5,IF(COUNTIF('Knockout & Winner'!$G$13:$G$28,L29)>0,3,0))))))) -> 0 | P29: =N29+O29 -> 0 | Q29: =IF(OR(COUNTIF('Knockout & Winner'!$G$13:$G$28,L29)>0,COUNTIF('Knockout & Winner'!$G$32:$G$39,L29)>0,COUNTIF('Knockout & Winner'!$G$43:$G$46,L29)>0,COUNTIF('Knockout & Winner'!$G$50:$G$51,L29)>0,'Knockout & Winner'!$G$55=L29,'Knockout & Winner'!$G$59=L29),"Yes","")
A30: =L19 -> Morocco | B30: =M19 -> 0 | C30: C | D30: =N19 -> 0 | E30: =IF(O19=25,"Champion",IF(OR('Knockout & Winner'!$B$59=L19,'Knockout & Winner'!$E$59=L19),"Finalist",IF(O19=15,"3rd Place",IF(O19=12,"Semi-final",IF(O19=8,"Quarter-final",IF(O19=5,"Round of 16",IF(O19=3,"Round of 32","—"))))))) -> — | F30: =O19 -> 0 | G30: =P19 -> 0 | L30: Netherlands | M30: =IFERROR(VLOOKUP(L30,'Participating Teams'!$B$4:$F$51,5,FALSE),"") -> 0 | N30: =IFERROR(INDEX('Group Stage'!$I$1:$I$200,MATCH(L30,'Group Stage'!$A$1:$A$200,0)),0) -> 0 | O30: =IF(AND('Knockout & Winner'!$G$59<>"",'Knockout & Winner'!$G$59=L30),25,IF(AND('Knockout & Winner'!$G$55<>"",'Knockout & Winner'!$G$55=L30),15,IF(OR(AND('Knockout & Winner'!$B$59<>"",'Knockout & Winner'!$B$59=L30),AND('Knockout & Winner'!$E$59<>"",'Knockout & Winner'!$E$59=L30)),18,IF(COUNTIF('Knockout & Winner'!$G$50:$G$51,L30)>0,12,IF(COUNTIF('Knockout & Winner'!$G$43:$G$46,L30)>0,8,IF(COUNTIF('Knockout & Winner'!$G$32:$G$39,L30)>0,5,IF(COUNTIF('Knockout & Winner'!$G$13:$G$28,L30)>0,3,0))))))) -> 0 | P30: =N30+O30 -> 0 | Q30: =IF(OR(COUNTIF('Knockout & Winner'!$G$13:$G$28,L30)>0,COUNTIF('Knockout & Winner'!$G$32:$G$39,L30)>0,COUNTIF('Knockout & Winner'!$G$43:$G$46,L30)>0,COUNTIF('Knockout & Winner'!$G$50:$G$51,L30)>0,'Knockout & Winner'!$G$55=L30,'Knockout & Winner'!$G$59=L30),"Yes","")
A31: =L20 -> Scotland | B31: =M20 -> 0 | C31: C | D31: =N20 -> 0 | E31: =IF(O20=25,"Champion",IF(OR('Knockout & Winner'!$B$59=L20,'Knockout & Winner'!$E$59=L20),"Finalist",IF(O20=15,"3rd Place",IF(O20=12,"Semi-final",IF(O20=8,"Quarter-final",IF(O20=5,"Round of 16",IF(O20=3,"Round of 32","—"))))))) -> — | F31: =O20 -> 0 | G31: =P20 -> 0 | L31: Japan | M31: =IFERROR(VLOOKUP(L31,'Participating Teams'!$B$4:$F$51,5,FALSE),"") -> 0 | N31: =IFERROR(INDEX('Group Stage'!$I$1:$I$200,MATCH(L31,'Group Stage'!$A$1:$A$200,0)),0) -> 0 | O31: =IF(AND('Knockout & Winner'!$G$59<>"",'Knockout & Winner'!$G$59=L31),25,IF(AND('Knockout & Winner'!$G$55<>"",'Knockout & Winner'!$G$55=L31),15,IF(OR(AND('Knockout & Winner'!$B$59<>"",'Knockout & Winner'!$B$59=L31),AND('Knockout & Winner'!$E$59<>"",'Knockout & Winner'!$E$59=L31)),18,IF(COUNTIF('Knockout & Winner'!$G$50:$G$51,L31)>0,12,IF(COUNTIF('Knockout & Winner'!$G$43:$G$46,L31)>0,8,IF(COUNTIF('Knockout & Winner'!$G$32:$G$39,L31)>0,5,IF(COUNTIF('Knockout & Winner'!$G$13:$G$28,L31)>0,3,0))))))) -> 0 | P31: =N31+O31 -> 0 | Q31: =IF(OR(COUNTIF('Knockout & Winner'!$G$13:$G$28,L31)>0,COUNTIF('Knockout & Winner'!$G$32:$G$39,L31)>0,COUNTIF('Knockout & Winner'!$G$43:$G$46,L31)>0,COUNTIF('Knockout & Winner'!$G$50:$G$51,L31)>0,'Knockout & Winner'!$G$55=L31,'Knockout & Winner'!$G$59=L31),"Yes","")
A32: =L21 -> Haiti | B32: =M21 -> 0 | C32: C | D32: =N21 -> 0 | E32: =IF(O21=25,"Champion",IF(OR('Knockout & Winner'!$B$59=L21,'Knockout & Winner'!$E$59=L21),"Finalist",IF(O21=15,"3rd Place",IF(O21=12,"Semi-final",IF(O21=8,"Quarter-final",IF(O21=5,"Round of 16",IF(O21=3,"Round of 32","—"))))))) -> — | F32: =O21 -> 0 | G32: =P21 -> 0 | L32: Tunisia | M32: =IFERROR(VLOOKUP(L32,'Participating Teams'!$B$4:$F$51,5,FALSE),"") -> 0 | N32: =IFERROR(INDEX('Group Stage'!$I$1:$I$200,MATCH(L32,'Group Stage'!$A$1:$A$200,0)),0) -> 0 | O32: =IF(AND('Knockout & Winner'!$G$59<>"",'Knockout & Winner'!$G$59=L32),25,IF(AND('Knockout & Winner'!$G$55<>"",'Knockout & Winner'!$G$55=L32),15,IF(OR(AND('Knockout & Winner'!$B$59<>"",'Knockout & Winner'!$B$59=L32),AND('Knockout & Winner'!$E$59<>"",'Knockout & Winner'!$E$59=L32)),18,IF(COUNTIF('Knockout & Winner'!$G$50:$G$51,L32)>0,12,IF(COUNTIF('Knockout & Winner'!$G$43:$G$46,L32)>0,8,IF(COUNTIF('Knockout & Winner'!$G$32:$G$39,L32)>0,5,IF(COUNTIF('Knockout & Winner'!$G$13:$G$28,L32)>0,3,0))))))) -> 0 | P32: =N32+O32 -> 0 | Q32: =IF(OR(COUNTIF('Knockout & Winner'!$G$13:$G$28,L32)>0,COUNTIF('Knockout & Winner'!$G$32:$G$39,L32)>0,COUNTIF('Knockout & Winner'!$G$43:$G$46,L32)>0,COUNTIF('Knockout & Winner'!$G$50:$G$51,L32)>0,'Knockout & Winner'!$G$55=L32,'Knockout & Winner'!$G$59=L32),"Yes","")
... A57: =L46 -> Argentina | B57: =M46 -> 0 | C57: J | D57: =N46 -> 0 | E57: =IF(O46=25,"Champion",IF(OR('Knockout & Winner'!$B$59=L46,'Knockout & Winner'!$E$59=L46),"Finalist",IF(O46=15,"3rd Place",IF(O46=12,"Semi-final",IF(O46=8,"Quarter-final",IF(O46=5,"Round of 16",IF(O46=3,"Round of 32","—"))))))) -> — | F57: =O46 -> 0 | G57: =P46 -> 0 | L57: Panama | M57: =IFERROR(VLOOKUP(L57,'Participating Teams'!$B$4:$F$51,5,FALSE),"") -> 0 | N57: =IFERROR(INDEX('Group Stage'!$I$1:$I$200,MATCH(L57,'Group Stage'!$A$1:$A$200,0)),0) -> 0 | O57: =IF(AND('Knockout & Winner'!$G$59<>"",'Knockout & Winner'!$G$59=L57),25,IF(AND('Knockout & Winner'!$G$55<>"",'Knockout & Winner'!$G$55=L57),15,IF(OR(AND('Knockout & Winner'!$B$59<>"",'Knockout & Winner'!$B$59=L57),AND('Knockout & Winner'!$E$59<>"",'Knockout & Winner'!$E$59=L57)),18,IF(COUNTIF('Knockout & Winner'!$G$50:$G$51,L57)>0,12,IF(COUNTIF('Knockout & Winner'!$G$43:$G$46,L57)>0,8,IF(COUNTIF('Knockout & Winner'!$G$32:$G$39,L57)>0,5,IF(COUNTIF('Knockout & Winner'!$G$13:$G$28,L57)>0,3,0))))))) -> 0 | P57: =N57+O57 -> 0 | Q57: =IF(OR(COUNTIF('Knockout & Winner'!$G$13:$G$28,L57)>0,COUNTIF('Knockout & Winner'!$G$32:$G$39,L57)>0,COUNTIF('Knockout & Winner'!$G$43:$G$46,L57)>0,COUNTIF('Knockout & Winner'!$G$50:$G$51,L57)>0,'Knockout & Winner'!$G$55=L57,'Knockout & Winner'!$G$59=L57),"Yes","")
A58: =L47 -> Algeria | B58: =M47 -> 0 | C58: J | D58: =N47 -> 0 | E58: =IF(O47=25,"Champion",IF(OR('Knockout & Winner'!$B$59=L47,'Knockout & Winner'!$E$59=L47),"Finalist",IF(O47=15,"3rd Place",IF(O47=12,"Semi-final",IF(O47=8,"Quarter-final",IF(O47=5,"Round of 16",IF(O47=3,"Round of 32","—"))))))) -> — | F58: =O47 -> 0 | G58: =P47 -> 0
A59: =L48 -> Austria | B59: =M48 -> 0 | C59: J | D59: =N48 -> 0 | E59: =IF(O48=25,"Champion",IF(OR('Knockout & Winner'!$B$59=L48,'Knockout & Winner'!$E$59=L48),"Finalist",IF(O48=15,"3rd Place",IF(O48=12,"Semi-final",IF(O48=8,"Quarter-final",IF(O48=5,"Round of 16",IF(O48=3,"Round of 32","—"))))))) -> — | F59: =O48 -> 0 | G59: =P48 -> 0
A60: =L49 -> Jordan | B60: =M49 -> 0 | C60: J | D60: =N49 -> 0 | E60: =IF(O49=25,"Champion",IF(OR('Knockout & Winner'!$B$59=L49,'Knockout & Winner'!$E$59=L49),"Finalist",IF(O49=15,"3rd Place",IF(O49=12,"Semi-final",IF(O49=8,"Quarter-final",IF(O49=5,"Round of 16",IF(O49=3,"Round of 32","—"))))))) -> — | F60: =O49 -> 0 | G60: =P49 -> 0
A61: =L50 -> Portugal | B61: =M50 -> 0 | C61: K | D61: =N50 -> 0 | E61: =IF(O50=25,"Champion",IF(OR('Knockout & Winner'!$B$59=L50,'Knockout & Winner'!$E$59=L50),"Finalist",IF(O50=15,"3rd Place",IF(O50=12,"Semi-final",IF(O50=8,"Quarter-final",IF(O50=5,"Round of 16",IF(O50=3,"Round of 32","—"))))))) -> — | F61: =O50 -> 0 | G61: =P50 -> 0
A62: =L51 -> Colombia | B62: =M51 -> 0 | C62: K | D62: =N51 -> 0 | E62: =IF(O51=25,"Champion",IF(OR('Knockout & Winner'!$B$59=L51,'Knockout & Winner'!$E$59=L51),"Finalist",IF(O51=15,"3rd Place",IF(O51=12,"Semi-final",IF(O51=8,"Quarter-final",IF(O51=5,"Round of 16",IF(O51=3,"Round of 32","—"))))))) -> — | F62: =O51 -> 0 | G62: =P51 -> 0
A63: =L52 -> Uzbekistan | B63: =M52 -> 0 | C63: K | D63: =N52 -> 0 | E63: =IF(O52=25,"Champion",IF(OR('Knockout & Winner'!$B$59=L52,'Knockout & Winner'!$E$59=L52),"Finalist",IF(O52=15,"3rd Place",IF(O52=12,"Semi-final",IF(O52=8,"Quarter-final",IF(O52=5,"Round of 16",IF(O52=3,"Round of 32","—"))))))) -> — | F63: =O52 -> 0 | G63: =P52 -> 0
A64: =L53 -> DR Congo | B64: =M53 -> 0 | C64: K | D64: =N53 -> 0 | E64: =IF(O53=25,"Champion",IF(OR('Knockout & Winner'!$B$59=L53,'Knockout & Winner'!$E$59=L53),"Finalist",IF(O53=15,"3rd Place",IF(O53=12,"Semi-final",IF(O53=8,"Quarter-final",IF(O53=5,"Round of 16",IF(O53=3,"Round of 32","—"))))))) -> — | F64: =O53 -> 0 | G64: =P53 -> 0
A65: =L54 -> England | B65: =M54 -> 0 | C65: L | D65: =N54 -> 0 | E65: =IF(O54=25,"Champion",IF(OR('Knockout & Winner'!$B$59=L54,'Knockout & Winner'!$E$59=L54),"Finalist",IF(O54=15,"3rd Place",IF(O54=12,"Semi-final",IF(O54=8,"Quarter-final",IF(O54=5,"Round of 16",IF(O54=3,"Round of 32","—"))))))) -> — | F65: =O54 -> 0 | G65: =P54 -> 0
A66: =L55 -> Croatia | B66: =M55 -> 0 | C66: L | D66: =N55 -> 0 | E66: =IF(O55=25,"Champion",IF(OR('Knockout & Winner'!$B$59=L55,'Knockout & Winner'!$E$59=L55),"Finalist",IF(O55=15,"3rd Place",IF(O55=12,"Semi-final",IF(O55=8,"Quarter-final",IF(O55=5,"Round of 16",IF(O55=3,"Round of 32","—"))))))) -> — | F66: =O55 -> 0 | G66: =P55 -> 0
...

Sheet Team Allocations
A1: FIFA World Cup 2026 Sweepstake — Team Allocations
A2: Each member draws 6 teams. Fill the cells below after the draw — pick from the dropdown in each cell.
B3: Poppa | C3: Nana | D3: Craig | E3: Anna | F3: Brooke | G3: Lachlan | H3: Sienna | I3: Brent
A4: Team 1 | B4: France | C4: Brazil | D4: Argentina | E4: Morocco | F4: Spain | G4: England | H4: Netherlands | I4: Portugal
A5: Team 2 | B5: DR Congo | C5: Cabo Verde | D5: Egypt | E5: Australia | F5: Qatar | G5: Croatia | H5: Türkiye | I5: Iran
A6: Team 3 | B6: Bosnia and Herzegovina | C6: Mexico | D6: United States | E6: Côte d'Ivoire | F6: Switzerland | G6: Jordan | H6: New Zealand | I6: Germany
A7: Team 4 | B7: Ghana | C7: Saudi Arabia | D7: Paraguay | E7: Ecuador | F7: Curaçao | G7: Japan | H7: Haiti | I7: Czechia
A8: Team 5 | B8: Scotland | C8: Belgium | D8: Colombia | E8: Iraq | F8: Algeria | G8: Austria | H8: Norway | I8: Uzbekistan
A9: Team 6 | B9: Senegal | C9: South Africa | D9: Uruguay | E9: Panama | F9: South Korea | G9: Canada | H9: Tunisia | I9: Sweden
A10: Count | B10: =COUNTA(B4:B9) -> 6 | C10: =COUNTA(C4:C9) -> 6 | D10: =COUNTA(D4:D9) -> 6 | E10: =COUNTA(E4:E9) -> 6 | F10: =COUNTA(F4:F9) -> 6 | G10: =COUNTA(G4:G9) -> 6 | H10: =COUNTA(H4:H9) -> 6 | I10: =COUNTA(I4:I9) -> 6
A12: How it works:
A13: • 48 teams ÷ 8 members = 6 teams each.
A14: • After the live draw, type or select each member's 6 teams in their column.
A15: • The 'Count' row should read 6 for every member once the draw is complete.
A16: • The 'Participating Teams' tab lists all 48 teams with their group and FIFA ranking.

Sheet Group Stage
A1: FIFA World Cup 2026 — Group Stage Tracker
A2: Enter each match score in the yellow cells — standings update automatically. Top 2 of each group + the 8 best 3rd-place teams advance to the Round of 32.
A4: GROUP A | M4: Matches (enter scores)
A5: Team | B5: P | C5: W | D5: D | E5: L | F5: GF | G5: GA | H5: GD | I5: Pts | J5: Pos | K5: Key | M5: Home | Q5: Away
A6: Mexico | B6: =C6+D6+E6 -> 0 | C6: =IF(AND(N6<>"",P6<>"",N6>P6),1,0)+IF(AND(N7<>"",P7<>"",N7>P7),1,0)+IF(AND(N8<>"",P8<>"",N8>P8),1,0) -> 0 | D6: =IF(AND(N6<>"",P6<>"",N6=P6),1,0)+IF(AND(N7<>"",P7<>"",N7=P7),1,0)+IF(AND(N8<>"",P8<>"",N8=P8),1,0) -> 0 | E6: =IF(AND(N6<>"",P6<>"",N6<P6),1,0)+IF(AND(N7<>"",P7<>"",N7<P7),1,0)+IF(AND(N8<>"",P8<>"",N8<P8),1,0) -> 0 | F6: =IF(N6<>"",N6,0)+IF(N7<>"",N7,0)+IF(N8<>"",N8,0) -> 0 | G6: =IF(P6<>"",P6,0)+IF(P7<>"",P7,0)+IF(P8<>"",P8,0) -> 0 | H6: =F6-G6 -> 0 | I6: =C6*3+D6 -> 0 | J6: =RANK(K6,K6:K9) -> 1 | K6: =I6*10000+H6*100+F6 -> 0 | M6: =A6 -> Mexico | O6: v | Q6: =A7 -> South Korea
A7: South Korea | B7: =C7+D7+E7 -> 0 | C7: =IF(AND(P6<>"",N6<>"",P6>N6),1,0)+IF(AND(N9<>"",P9<>"",N9>P9),1,0)+IF(AND(N10<>"",P10<>"",N10>P10),1,0) -> 0 | D7: =IF(AND(P6<>"",N6<>"",P6=N6),1,0)+IF(AND(N9<>"",P9<>"",N9=P9),1,0)+IF(AND(N10<>"",P10<>"",N10=P10),1,0) -> 0 | E7: =IF(AND(P6<>"",N6<>"",P6<N6),1,0)+IF(AND(N9<>"",P9<>"",N9<P9),1,0)+IF(AND(N10<>"",P10<>"",N10<P10),1,0) -> 0 | F7: =IF(P6<>"",P6,0)+IF(N9<>"",N9,0)+IF(N10<>"",N10,0) -> 0 | G7: =IF(N6<>"",N6,0)+IF(P9<>"",P9,0)+IF(P10<>"",P10,0) -> 0 | H7: =F7-G7 -> 0 | I7: =C7*3+D7 -> 0 | J7: =RANK(K7,K6:K9) -> 1 | K7: =I7*10000+H7*100+F7 -> 0 | M7: =A6 -> Mexico | O7: v | Q7: =A8 -> South Africa
A8: South Africa | B8: =C8+D8+E8 -> 0 | C8: =IF(AND(P7<>"",N7<>"",P7>N7),1,0)+IF(AND(P9<>"",N9<>"",P9>N9),1,0)+IF(AND(N11<>"",P11<>"",N11>P11),1,0) -> 0 | D8: =IF(AND(P7<>"",N7<>"",P7=N7),1,0)+IF(AND(P9<>"",N9<>"",P9=N9),1,0)+IF(AND(N11<>"",P11<>"",N11=P11),1,0) -> 0 | E8: =IF(AND(P7<>"",N7<>"",P7<N7),1,0)+IF(AND(P9<>"",N9<>"",P9<N9),1,0)+IF(AND(N11<>"",P11<>"",N11<P11),1,0) -> 0 | F8: =IF(P7<>"",P7,0)+IF(P9<>"",P9,0)+IF(N11<>"",N11,0) -> 0 | G8: =IF(N7<>"",N7,0)+IF(N9<>"",N9,0)+IF(P11<>"",P11,0) -> 0 | H8: =F8-G8 -> 0 | I8: =C8*3+D8 -> 0 | J8: =RANK(K8,K6:K9) -> 1 | K8: =I8*10000+H8*100+F8 -> 0 | M8: =A6 -> Mexico | O8: v | Q8: =A9 -> Czechia
A9: Czechia | B9: =C9+D9+E9 -> 0 | C9: =IF(AND(P8<>"",N8<>"",P8>N8),1,0)+IF(AND(P10<>"",N10<>"",P10>N10),1,0)+IF(AND(P11<>"",N11<>"",P11>N11),1,0) -> 0 | D9: =IF(AND(P8<>"",N8<>"",P8=N8),1,0)+IF(AND(P10<>"",N10<>"",P10=N10),1,0)+IF(AND(P11<>"",N11<>"",P11=N11),1,0) -> 0 | E9: =IF(AND(P8<>"",N8<>"",P8<N8),1,0)+IF(AND(P10<>"",N10<>"",P10<N10),1,0)+IF(AND(P11<>"",N11<>"",P11<N11),1,0) -> 0 | F9: =IF(P8<>"",P8,0)+IF(P10<>"",P10,0)+IF(P11<>"",P11,0) -> 0 | G9: =IF(N8<>"",N8,0)+IF(N10<>"",N10,0)+IF(N11<>"",N11,0) -> 0 | H9: =F9-G9 -> 0 | I9: =C9*3+D9 -> 0 | J9: =RANK(K9,K6:K9) -> 1 | K9: =I9*10000+H9*100+F9 -> 0 | M9: =A7 -> South Korea | O9: v | Q9: =A8 -> South Africa
M10: =A7 -> South Korea | O10: v | Q10: =A9 -> Czechia
M11: =A8 -> South Africa | O11: v | Q11: =A9 -> Czechia
A13: GROUP B | M13: Matches (enter scores)
A14: Team | B14: P | C14: W | D14: D | E14: L | F14: GF | G14: GA | H14: GD | I14: Pts | J14: Pos | K14: Key | M14: Home | Q14: Away
A15: Canada | B15: =C15+D15+E15 -> 0 | C15: =IF(AND(N15<>"",P15<>"",N15>P15),1,0)+IF(AND(N16<>"",P16<>"",N16>P16),1,0)+IF(AND(N17<>"",P17<>"",N17>P17),1,0) -> 0 | D15: =IF(AND(N15<>"",P15<>"",N15=P15),1,0)+IF(AND(N16<>"",P16<>"",N16=P16),1,0)+IF(AND(N17<>"",P17<>"",N17=P17),1,0) -> 0 | E15: =IF(AND(N15<>"",P15<>"",N15<P15),1,0)+IF(AND(N16<>"",P16<>"",N16<P16),1,0)+IF(AND(N17<>"",P17<>"",N17<P17),1,0) -> 0 | F15: =IF(N15<>"",N15,0)+IF(N16<>"",N16,0)+IF(N17<>"",N17,0) -> 0 | G15: =IF(P15<>"",P15,0)+IF(P16<>"",P16,0)+IF(P17<>"",P17,0) -> 0 | H15: =F15-G15 -> 0 | I15: =C15*3+D15 -> 0 | J15: =RANK(K15,K15:K18) -> 1 | K15: =I15*10000+H15*100+F15 -> 0 | M15: =A15 -> Canada | O15: v | Q15: =A16 -> Switzerland
A16: Switzerland | B16: =C16+D16+E16 -> 0 | C16: =IF(AND(P15<>"",N15<>"",P15>N15),1,0)+IF(AND(N18<>"",P18<>"",N18>P18),1,0)+IF(AND(N19<>"",P19<>"",N19>P19),1,0) -> 0 | D16: =IF(AND(P15<>"",N15<>"",P15=N15),1,0)+IF(AND(N18<>"",P18<>"",N18=P18),1,0)+IF(AND(N19<>"",P19<>"",N19=P19),1,0) -> 0 | E16: =IF(AND(P15<>"",N15<>"",P15<N15),1,0)+IF(AND(N18<>"",P18<>"",N18<P18),1,0)+IF(AND(N19<>"",P19<>"",N19<P19),1,0) -> 0 | F16: =IF(P15<>"",P15,0)+IF(N18<>"",N18,0)+IF(N19<>"",N19,0) -> 0 | G16: =IF(N15<>"",N15,0)+IF(P18<>"",P18,0)+IF(P19<>"",P19,0) -> 0 | H16: =F16-G16 -> 0 | I16: =C16*3+D16 -> 0 | J16: =RANK(K16,K15:K18) -> 1 | K16: =I16*10000+H16*100+F16 -> 0 | M16: =A15 -> Canada | O16: v | Q16: =A17 -> Qatar
A17: Qatar | B17: =C17+D17+E17 -> 0 | C17: =IF(AND(P16<>"",N16<>"",P16>N16),1,0)+IF(AND(P18<>"",N18<>"",P18>N18),1,0)+IF(AND(N20<>"",P20<>"",N20>P20),1,0) -> 0 | D17: =IF(AND(P16<>"",N16<>"",P16=N16),1,0)+IF(AND(P18<>"",N18<>"",P18=N18),1,0)+IF(AND(N20<>"",P20<>"",N20=P20),1,0) -> 0 | E17: =IF(AND(P16<>"",N16<>"",P16<N16),1,0)+IF(AND(P18<>"",N18<>"",P18<N18),1,0)+IF(AND(N20<>"",P20<>"",N20<P20),1,0) -> 0 | F17: =IF(P16<>"",P16,0)+IF(P18<>"",P18,0)+IF(N20<>"",N20,0) -> 0 | G17: =IF(N16<>"",N16,0)+IF(N18<>"",N18,0)+IF(P20<>"",P20,0) -> 0 | H17: =F17-G17 -> 0 | I17: =C17*3+D17 -> 0 | J17: =RANK(K17,K15:K18) -> 1 | K17: =I17*10000+H17*100+F17 -> 0 | M17: =A15 -> Canada | O17: v | Q17: =A18 -> Bosnia and Herzegovina
A18: Bosnia and Herzegovina | B18: =C18+D18+E18 -> 0 | C18: =IF(AND(P17<>"",N17<>"",P17>N17),1,0)+IF(AND(P19<>"",N19<>"",P19>N19),1,0)+IF(AND(P20<>"",N20<>"",P20>N20),1,0) -> 0 | D18: =IF(AND(P17<>"",N17<>"",P17=N17),1,0)+IF(AND(P19<>"",N19<>"",P19=N19),1,0)+IF(AND(P20<>"",N20<>"",P20=N20),1,0) -> 0 | E18: =IF(AND(P17<>"",N17<>"",P17<N17),1,0)+IF(AND(P19<>"",N19<>"",P19<N19),1,0)+IF(AND(P20<>"",N20<>"",P20<N20),1,0) -> 0 | F18: =IF(P17<>"",P17,0)+IF(P19<>"",P19,0)+IF(P20<>"",P20,0) -> 0 | G18: =IF(N17<>"",N17,0)+IF(N19<>"",N19,0)+IF(N20<>"",N20,0) -> 0 | H18: =F18-G18 -> 0 | I18: =C18*3+D18 -> 0 | J18: =RANK(K18,K15:K18) -> 1 | K18: =I18*10000+H18*100+F18 -> 0 | M18: =A16 -> Switzerland | O18: v | Q18: =A17 -> Qatar
M19: =A16 -> Switzerland | O19: v | Q19: =A18 -> Bosnia and Herzegovina
M20: =A17 -> Qatar | O20: v | Q20: =A18 -> Bosnia and Herzegovina
A22: GROUP C | M22: Matches (enter scores)
A23: Team | B23: P | C23: W | D23: D | E23: L | F23: GF | G23: GA | H23: GD | I23: Pts | J23: Pos | K23: Key | M23: Home | Q23: Away
A24: Brazil | B24: =C24+D24+E24 -> 0 | C24: =IF(AND(N24<>"",P24<>"",N24>P24),1,0)+IF(AND(N25<>"",P25<>"",N25>P25),1,0)+IF(AND(N26<>"",P26<>"",N26>P26),1,0) -> 0 | D24: =IF(AND(N24<>"",P24<>"",N24=P24),1,0)+IF(AND(N25<>"",P25<>"",N25=P25),1,0)+IF(AND(N26<>"",P26<>"",N26=P26),1,0) -> 0 | E24: =IF(AND(N24<>"",P24<>"",N24<P24),1,0)+IF(AND(N25<>"",P25<>"",N25<P25),1,0)+IF(AND(N26<>"",P26<>"",N26<P26),1,0) -> 0 | F24: =IF(N24<>"",N24,0)+IF(N25<>"",N25,0)+IF(N26<>"",N26,0) -> 0 | G24: =IF(P24<>"",P24,0)+IF(P25<>"",P25,0)+IF(P26<>"",P26,0) -> 0 | H24: =F24-G24 -> 0 | I24: =C24*3+D24 -> 0 | J24: =RANK(K24,K24:K27) -> 1 | K24: =I24*10000+H24*100+F24 -> 0 | M24: =A24 -> Brazil | O24: v | Q24: =A25 -> Morocco
A25: Morocco | B25: =C25+D25+E25 -> 0 | C25: =IF(AND(P24<>"",N24<>"",P24>N24),1,0)+IF(AND(N27<>"",P27<>"",N27>P27),1,0)+IF(AND(N28<>"",P28<>"",N28>P28),1,0) -> 0 | D25: =IF(AND(P24<>"",N24<>"",P24=N24),1,0)+IF(AND(N27<>"",P27<>"",N27=P27),1,0)+IF(AND(N28<>"",P28<>"",N28=P28),1,0) -> 0 | E25: =IF(AND(P24<>"",N24<>"",P24<N24),1,0)+IF(AND(N27<>"",P27<>"",N27<P27),1,0)+IF(AND(N28<>"",P28<>"",N28<P28),1,0) -> 0 | F25: =IF(P24<>"",P24,0)+IF(N27<>"",N27,0)+IF(N28<>"",N28,0) -> 0 | G25: =IF(N24<>"",N24,0)+IF(P27<>"",P27,0)+IF(P28<>"",P28,0) -> 0 | H25: =F25-G25 -> 0 | I25: =C25*3+D25 -> 0 | J25: =RANK(K25,K24:K27) -> 1 | K25: =I25*10000+H25*100+F25 -> 0 | M25: =A24 -> Brazil | O25: v | Q25: =A26 -> Scotland
A26: Scotland | B26: =C26+D26+E26 -> 0 | C26: =IF(AND(P25<>"",N25<>"",P25>N25),1,0)+IF(AND(P27<>"",N27<>"",P27>N27),1,0)+IF(AND(N29<>"",P29<>"",N29>P29),1,0) -> 0 | D26: =IF(AND(P25<>"",N25<>"",P25=N25),1,0)+IF(AND(P27<>"",N27<>"",P27=N27),1,0)+IF(AND(N29<>"",P29<>"",N29=P29),1,0) -> 0 | E26: =IF(AND(P25<>"",N25<>"",P25<N25),1,0)+IF(AND(P27<>"",N27<>"",P27<N27),1,0)+IF(AND(N29<>"",P29<>"",N29<P29),1,0) -> 0 | F26: =IF(P25<>"",P25,0)+IF(P27<>"",P27,0)+IF(N29<>"",N29,0) -> 0 | G26: =IF(N25<>"",N25,0)+IF(N27<>"",N27,0)+IF(P29<>"",P29,0) -> 0 | H26: =F26-G26 -> 0 | I26: =C26*3+D26 -> 0 | J26: =RANK(K26,K24:K27) -> 1 | K26: =I26*10000+H26*100+F26 -> 0 | M26: =A24 -> Brazil | O26: v | Q26: =A27 -> Haiti
A27: Haiti | B27: =C27+D27+E27 -> 0 | C27: =IF(AND(P26<>"",N26<>"",P26>N26),1,0)+IF(AND(P28<>"",N28<>"",P28>N28),1,0)+IF(AND(P29<>"",N29<>"",P29>N29),1,0) -> 0 | D27: =IF(AND(P26<>"",N26<>"",P26=N26),1,0)+IF(AND(P28<>"",N28<>"",P28=N28),1,0)+IF(AND(P29<>"",N29<>"",P29=N29),1,0) -> 0 | E27: =IF(AND(P26<>"",N26<>"",P26<N26),1,0)+IF(AND(P28<>"",N28<>"",P28<N28),1,0)+IF(AND(P29<>"",N29<>"",P29<N29),1,0) -> 0 | F27: =IF(P26<>"",P26,0)+IF(P28<>"",P28,0)+IF(P29<>"",P29,0) -> 0 | G27: =IF(N26<>"",N26,0)+IF(N28<>"",N28,0)+IF(N29<>"",N29,0) -> 0 | H27: =F27-G27 -> 0 | I27: =C27*3+D27 -> 0 | J27: =RANK(K27,K24:K27) -> 1 | K27: =I27*10000+H27*100+F27 -> 0 | M27: =A25 -> Morocco | O27: v | Q27: =A26 -> Scotland
M28: =A25 -> Morocco | O28: v | Q28: =A27 -> Haiti
M29: =A26 -> Scotland | O29: v | Q29: =A27 -> Haiti
A31: GROUP D | M31: Matches (enter scores)
A32: Team | B32: P | C32: W | D32: D | E32: L | F32: GF | G32: GA | H32: GD | I32: Pts | J32: Pos | K32: Key | M32: Home | Q32: Away
A33: United States | B33: =C33+D33+E33 -> 0 | C33: =IF(AND(N33<>"",P33<>"",N33>P33),1,0)+IF(AND(N34<>"",P34<>"",N34>P34),1,0)+IF(AND(N35<>"",P35<>"",N35>P35),1,0) -> 0 | D33: =IF(AND(N33<>"",P33<>"",N33=P33),1,0)+IF(AND(N34<>"",P34<>"",N34=P34),1,0)+IF(AND(N35<>"",P35<>"",N35=P35),1,0) -> 0 | E33: =IF(AND(N33<>"",P33<>"",N33<P33),1,0)+IF(AND(N34<>"",P34<>"",N34<P34),1,0)+IF(AND(N35<>"",P35<>"",N35<P35),1,0) -> 0 | F33: =IF(N33<>"",N33,0)+IF(N34<>"",N34,0)+IF(N35<>"",N35,0) -> 0 | G33: =IF(P33<>"",P33,0)+IF(P34<>"",P34,0)+IF(P35<>"",P35,0) -> 0 | H33: =F33-G33 -> 0 | I33: =C33*3+D33 -> 0 | J33: =RANK(K33,K33:K36) -> 1 | K33: =I33*10000+H33*100+F33 -> 0 | M33: =A33 -> United States | O33: v | Q33: =A34 -> Paraguay
A34: Paraguay | B34: =C34+D34+E34 -> 0 | C34: =IF(AND(P33<>"",N33<>"",P33>N33),1,0)+IF(AND(N36<>"",P36<>"",N36>P36),1,0)+IF(AND(N37<>"",P37<>"",N37>P37),1,0) -> 0 | D34: =IF(AND(P33<>"",N33<>"",P33=N33),1,0)+IF(AND(N36<>"",P36<>"",N36=P36),1,0)+IF(AND(N37<>"",P37<>"",N37=P37),1,0) -> 0 | E34: =IF(AND(P33<>"",N33<>"",P33<N33),1,0)+IF(AND(N36<>"",P36<>"",N36<P36),1,0)+IF(AND(N37<>"",P37<>"",N37<P37),1,0) -> 0 | F34: =IF(P33<>"",P33,0)+IF(N36<>"",N36,0)+IF(N37<>"",N37,0) -> 0 | G34: =IF(N33<>"",N33,0)+IF(P36<>"",P36,0)+IF(P37<>"",P37,0) -> 0 | H34: =F34-G34 -> 0 | I34: =C34*3+D34 -> 0 | J34: =RANK(K34,K33:K36) -> 1 | K34: =I34*10000+H34*100+F34 -> 0 | M34: =A33 -> United States | O34: v | Q34: =A35 -> Australia
A35: Australia | B35: =C35+D35+E35 -> 0 | C35: =IF(AND(P34<>"",N34<>"",P34>N34),1,0)+IF(AND(P36<>"",N36<>"",P36>N36),1,0)+IF(AND(N38<>"",P38<>"",N38>P38),1,0) -> 0 | D35: =IF(AND(P34<>"",N34<>"",P34=N34),1,0)+IF(AND(P36<>"",N36<>"",P36=N36),1,0)+IF(AND(N38<>"",P38<>"",N38=P38),1,0) -> 0 | E35: =IF(AND(P34<>"",N34<>"",P34<N34),1,0)+IF(AND(P36<>"",N36<>"",P36<N36),1,0)+IF(AND(N38<>"",P38<>"",N38<P38),1,0) -> 0 | F35: =IF(P34<>"",P34,0)+IF(P36<>"",P36,0)+IF(N38<>"",N38,0) -> 0 | G35: =IF(N34<>"",N34,0)+IF(N36<>"",N36,0)+IF(P38<>"",P38,0) -> 0 | H35: =F35-G35 -> 0 | I35: =C35*3+D35 -> 0 | J35: =RANK(K35,K33:K36) -> 1 | K35: =I35*10000+H35*100+F35 -> 0 | M35: =A33 -> United States | O35: v | Q35: =A36 -> Türkiye
A36: Türkiye | B36: =C36+D36+E36 -> 0 | C36: =IF(AND(P35<>"",N35<>"",P35>N35),1,0)+IF(AND(P37<>"",N37<>"",P37>N37),1,0)+IF(AND(P38<>"",N38<>"",P38>N38),1,0) -> 0 | D36: =IF(AND(P35<>"",N35<>"",P35=N35),1,0)+IF(AND(P37<>"",N37<>"",P37=N37),1,0)+IF(AND(P38<>"",N38<>"",P38=N38),1,0) -> 0 | E36: =IF(AND(P35<>"",N35<>"",P35<N35),1,0)+IF(AND(P37<>"",N37<>"",P37<N37),1,0)+IF(AND(P38<>"",N38<>"",P38<N38),1,0) -> 0 | F36: =IF(P35<>"",P35,0)+IF(P37<>"",P37,0)+IF(P38<>"",P38,0) -> 0 | G36: =IF(N35<>"",N35,0)+IF(N37<>"",N37,0)+IF(N38<>"",N38,0) -> 0 | H36: =F36-G36 -> 0 | I36: =C36*3+D36 -> 0 | J36: =RANK(K36,K33:K36) -> 1 | K36: =I36*10000+H36*100+F36 -> 0 | M36: =A34 -> Paraguay | O36: v | Q36: =A35 -> Australia
M37: =A34 -> Paraguay | O37: v | Q37: =A36 -> Türkiye
M38: =A35 -> Australia | O38: v | Q38: =A36 -> Türkiye
A40: GROUP E | M40: Matches (enter scores)
A41: Team | B41: P | C41: W | D41: D | E41: L | F41: GF | G41: GA | H41: GD | I41: Pts | J41: Pos | K41: Key | M41: Home | Q41: Away
A42: Germany | B42: =C42+D42+E42 -> 0 | C42: =IF(AND(N42<>"",P42<>"",N42>P42),1,0)+IF(AND(N43<>"",P43<>"",N43>P43),1,0)+IF(AND(N44<>"",P44<>"",N44>P44),1,0) -> 0 | D42: =IF(AND(N42<>"",P42<>"",N42=P42),1,0)+IF(AND(N43<>"",P43<>"",N43=P43),1,0)+IF(AND(N44<>"",P44<>"",N44=P44),1,0) -> 0 | E42: =IF(AND(N42<>"",P42<>"",N42<P42),1,0)+IF(AND(N43<>"",P43<>"",N43<P43),1,0)+IF(AND(N44<>"",P44<>"",N44<P44),1,0) -> 0 | F42: =IF(N42<>"",N42,0)+IF(N43<>"",N43,0)+IF(N44<>"",N44,0) -> 0 | G42: =IF(P42<>"",P42,0)+IF(P43<>"",P43,0)+IF(P44<>"",P44,0) -> 0 | H42: =F42-G42 -> 0 | I42: =C42*3+D42 -> 0 | J42: =RANK(K42,K42:K45) -> 1 | K42: =I42*10000+H42*100+F42 -> 0 | M42: =A42 -> Germany | O42: v | Q42: =A43 -> Ecuador
A43: Ecuador | B43: =C43+D43+E43 -> 0 | C43: =IF(AND(P42<>"",N42<>"",P42>N42),1,0)+IF(AND(N45<>"",P45<>"",N45>P45),1,0)+IF(AND(N46<>"",P46<>"",N46>P46),1,0) -> 0 | D43: =IF(AND(P42<>"",N42<>"",P42=N42),1,0)+IF(AND(N45<>"",P45<>"",N45=P45),1,0)+IF(AND(N46<>"",P46<>"",N46=P46),1,0) -> 0 | E43: =IF(AND(P42<>"",N42<>"",P42<N42),1,0)+IF(AND(N45<>"",P45<>"",N45<P45),1,0)+IF(AND(N46<>"",P46<>"",N46<P46),1,0) -> 0 | F43: =IF(P42<>"",P42,0)+IF(N45<>"",N45,0)+IF(N46<>"",N46,0) -> 0 | G43: =IF(N42<>"",N42,0)+IF(P45<>"",P45,0)+IF(P46<>"",P46,0) -> 0 | H43: =F43-G43 -> 0 | I43: =C43*3+D43 -> 0 | J43: =RANK(K43,K42:K45) -> 1 | K43: =I43*10000+H43*100+F43 -> 0 | M43: =A42 -> Germany | O43: v | Q43: =A44 -> Côte d'Ivoire
A44: Côte d'Ivoire | B44: =C44+D44+E44 -> 0 | C44: =IF(AND(P43<>"",N43<>"",P43>N43),1,0)+IF(AND(P45<>"",N45<>"",P45>N45),1,0)+IF(AND(N47<>"",P47<>"",N47>P47),1,0) -> 0 | D44: =IF(AND(P43<>"",N43<>"",P43=N43),1,0)+IF(AND(P45<>"",N45<>"",P45=N45),1,0)+IF(AND(N47<>"",P47<>"",N47=P47),1,0) -> 0 | E44: =IF(AND(P43<>"",N43<>"",P43<N43),1,0)+IF(AND(P45<>"",N45<>"",P45<N45),1,0)+IF(AND(N47<>"",P47<>"",N47<P47),1,0) -> 0 | F44: =IF(P43<>"",P43,0)+IF(P45<>"",P45,0)+IF(N47<>"",N47,0) -> 0 | G44: =IF(N43<>"",N43,0)+IF(N45<>"",N45,0)+IF(P47<>"",P47,0) -> 0 | H44: =F44-G44 -> 0 | I44: =C44*3+D44 -> 0 | J44: =RANK(K44,K42:K45) -> 1 | K44: =I44*10000+H44*100+F44 -> 0 | M44: =A42 -> Germany | O44: v | Q44: =A45 -> Curaçao
A45: Curaçao | B45: =C45+D45+E45 -> 0 | C45: =IF(AND(P44<>"",N44<>"",P44>N44),1,0)+IF(AND(P46<>"",N46<>"",P46>N46),1,0)+IF(AND(P47<>"",N47<>"",P47>N47),1,0) -> 0 | D45: =IF(AND(P44<>"",N44<>"",P44=N44),1,0)+IF(AND(P46<>"",N46<>"",P46=N46),1,0)+IF(AND(P47<>"",N47<>"",P47=N47),1,0) -> 0 | E45: =IF(AND(P44<>"",N44<>"",P44<N44),1,0)+IF(AND(P46<>"",N46<>"",P46<N46),1,0)+IF(AND(P47<>"",N47<>"",P47<N47),1,0) -> 0 | F45: =IF(P44<>"",P44,0)+IF(P46<>"",P46,0)+IF(P47<>"",P47,0) -> 0 | G45: =IF(N44<>"",N44,0)+IF(N46<>"",N46,0)+IF(N47<>"",N47,0) -> 0 | H45: =F45-G45 -> 0 | I45: =C45*3+D45 -> 0 | J45: =RANK(K45,K42:K45) -> 1 | K45: =I45*10000+H45*100+F45 -> 0 | M45: =A43 -> Ecuador | O45: v | Q45: =A44 -> Côte d'Ivoire
...

Sheet Knockout & Winner
A1: FIFA World Cup 2026 — Knockout Bracket & Winners
A2: Fill the 32 qualifiers into the Round of 32 (yellow), then enter scores as games are played — winners advance automatically. For a draw, type the team that won on penalties in the 'Pen. winner' cell.
A4: 🏆 TOURNAMENT WINNERS
A5: Result | B5: Team | G5: Owner (sweepstake)
A6: Champion | B6: =IF(G59="","",G59) | G6: =IFERROR(VLOOKUP(B6,'Participating Teams'!$B$4:$F$51,5,FALSE),"")
A7: Runner-up | B7: =IF(G59="","",IF(G59=B59,E59,B59)) | G7: =IFERROR(VLOOKUP(B7,'Participating Teams'!$B$4:$F$51,5,FALSE),"")
A8: Third place | B8: =IF(G55="","",G55) | G8: =IFERROR(VLOOKUP(B8,'Participating Teams'!$B$4:$F$51,5,FALSE),"")
A9: Fourth place | B9: =IF(G55="","",IF(G55=B55,E55,B55)) | G9: =IFERROR(VLOOKUP(B9,'Participating Teams'!$B$4:$F$51,5,FALSE),"")
A11: ROUND OF 32 · enter the 32 qualifiers and scores
A12: Match | B12: Home | E12: Away | F12: Pen. winner (if draw) | G12: Winner
A13: R32-1 | G13: =IF(OR(C13="",D13=""),"",IF(C13>D13,B13,IF(D13>C13,E13,F13)))
A14: R32-2 | G14: =IF(OR(C14="",D14=""),"",IF(C14>D14,B14,IF(D14>C14,E14,F14)))
A15: R32-3 | G15: =IF(OR(C15="",D15=""),"",IF(C15>D15,B15,IF(D15>C15,E15,F15)))
A16: R32-4 | G16: =IF(OR(C16="",D16=""),"",IF(C16>D16,B16,IF(D16>C16,E16,F16)))
A17: R32-5 | G17: =IF(OR(C17="",D17=""),"",IF(C17>D17,B17,IF(D17>C17,E17,F17)))
A18: R32-6 | G18: =IF(OR(C18="",D18=""),"",IF(C18>D18,B18,IF(D18>C18,E18,F18)))
A19: R32-7 | G19: =IF(OR(C19="",D19=""),"",IF(C19>D19,B19,IF(D19>C19,E19,F19)))
A20: R32-8 | G20: =IF(OR(C20="",D20=""),"",IF(C20>D20,B20,IF(D20>C20,E20,F20)))
A21: R32-9 | G21: =IF(OR(C21="",D21=""),"",IF(C21>D21,B21,IF(D21>C21,E21,F21)))
A22: R32-10 | G22: =IF(OR(C22="",D22=""),"",IF(C22>D22,B22,IF(D22>C22,E22,F22)))
A23: R32-11 | G23: =IF(OR(C23="",D23=""),"",IF(C23>D23,B23,IF(D23>C23,E23,F23)))
A24: R32-12 | G24: =IF(OR(C24="",D24=""),"",IF(C24>D24,B24,IF(D24>C24,E24,F24)))
... A28: R32-16 | G28: =IF(OR(C28="",D28=""),"",IF(C28>D28,B28,IF(D28>C28,E28,F28)))
A30: ROUND OF 16
A31: Match | B31: Home | E31: Away | F31: Pen. winner (if draw) | G31: Winner
A32: R16-1 | B32: =IF(G13="","",G13) | E32: =IF(G14="","",G14) | G32: =IF(OR(C32="",D32=""),"",IF(C32>D32,B32,IF(D32>C32,E32,F32)))
A33: R16-2 | B33: =IF(G15="","",G15) | E33: =IF(G16="","",G16) | G33: =IF(OR(C33="",D33=""),"",IF(C33>D33,B33,IF(D33>C33,E33,F33)))
A34: R16-3 | B34: =IF(G17="","",G17) | E34: =IF(G18="","",G18) | G34: =IF(OR(C34="",D34=""),"",IF(C34>D34,B34,IF(D34>C34,E34,F34)))
A35: R16-4 | B35: =IF(G19="","",G19) | E35: =IF(G20="","",G20) | G35: =IF(OR(C35="",D35=""),"",IF(C35>D35,B35,IF(D35>C35,E35,F35)))
A36: R16-5 | B36: =IF(G21="","",G21) | E36: =IF(G22="","",G22) | G36: =IF(OR(C36="",D36=""),"",IF(C36>D36,B36,IF(D36>C36,E36,F36)))
A37: R16-6 | B37: =IF(G23="","",G23) | E37: =IF(G24="","",G24) | G37: =IF(OR(C37="",D37=""),"",IF(C37>D37,B37,IF(D37>C37,E37,F37)))
A38: R16-7 | B38: =IF(G25="","",G25) | E38: =IF(G26="","",G26) | G38: =IF(OR(C38="",D38=""),"",IF(C38>D38,B38,IF(D38>C38,E38,F38)))
A39: R16-8 | B39: =IF(G27="","",G27) | E39: =IF(G28="","",G28) | G39: =IF(OR(C39="",D39=""),"",IF(C39>D39,B39,IF(D39>C39,E39,F39)))
A41: QUARTER-FINALS
A42: Match | B42: Home | E42: Away | F42: Pen. winner (if draw) | G42: Winner
A43: QF-1 | B43: =IF(G32="","",G32) | E43: =IF(G33="","",G33) | G43: =IF(OR(C43="",D43=""),"",IF(C43>D43,B43,IF(D43>C43,E43,F43)))
A44: QF-2 | B44: =IF(G34="","",G34) | E44: =IF(G35="","",G35) | G44: =IF(OR(C44="",D44=""),"",IF(C44>D44,B44,IF(D44>C44,E44,F44)))
A45: QF-3 | B45: =IF(G36="","",G36) | E45: =IF(G37="","",G37) | G45: =IF(OR(C45="",D45=""),"",IF(C45>D45,B45,IF(D45>C45,E45,F45)))
A46: QF-4 | B46: =IF(G38="","",G38) | E46: =IF(G39="","",G39) | G46: =IF(OR(C46="",D46=""),"",IF(C46>D46,B46,IF(D46>C46,E46,F46)))
A48: SEMI-FINALS
...

Sheet Participating Teams
A1: FIFA World Cup 2026 — 48 Participating Teams
A2: Hosted by Canada, Mexico & USA · 11 June – 19 July 2026 · 12 groups of 4
A3: # | B3: Team | C3: Group | D3: Confederation | E3: FIFA Rank | F3: Allocated To
A4: 1 | B4: Mexico | C4: A | D4: CONCACAF (Host) | E4: 15
A5: 2 | B5: South Korea | C5: A | D5: AFC | E5: 25
A6: 3 | B6: South Africa | C6: A | D6: CAF | E6: 60
A7: 4 | B7: Czechia | C7: A | D7: UEFA | E7: 41
A8: 5 | B8: Canada | C8: B | D8: CONCACAF (Host) | E8: 30
A9: 6 | B9: Switzerland | C9: B | D9: UEFA | E9: 19
A10: 7 | B10: Qatar | C10: B | D10: AFC | E10: 53
A11: 8 | B11: Bosnia and Herzegovina | C11: B | D11: UEFA | E11: 71
A12: 9 | B12: Brazil | C12: C | D12: CONMEBOL | E12: 6
A13: 10 | B13: Morocco | C13: C | D13: CAF | E13: 8
A14: 11 | B14: Scotland | C14: C | D14: UEFA | E14: 43
A15: 12 | B15: Haiti | C15: C | D15: CONCACAF | E15: 79
... A51: 48 | B51: Panama | C51: L | D51: CONCACAF | E51: 51
